Workbook

Sheet Cover
B2: =F6&" Financial Model" -> DTC Financial Model
B4: Scenario Analysis | E4: General Settings | H4: Table of Contents
B6: Active Scenario | C6: 3 | E6: Company Name | F6: DTC | H6: Cover Page
E7: Company Sector | F7: Ecommerce | H7: Income Statement
B8: Alerts | E8: Currency | F8: NAIRA | H8: Balance Sheet
E9: Last Update | F9: 46268 | H9: Cash Flow Statement
B10: Balance Sheet Balances? | C10: =IF(Forecast!O36=0,"✅ Balanced","❌ Error") -> ✅ Balanced | E10: Contact | F10: Tobou Egbekun | H10: Assumptions & Drivers
B11: Cash Position | C11: =IF(Forecast!O56>20000000,"Healthy",IF(Forecast!O56>8000000,"Warning","Critical")) -> Critical
B12: Net Income | C12: =IF(Forecast!O15>0,"✅ Profitable","⚠️ Loss") -> ⚠️ Loss
B13: Runway Remanining | C13: =IF(Forecast!O56<0,"❌ Insolvent",ROUND(Forecast!O56/ABS(Forecast!O43),1)&" months") -> ❌ Insolvent

Sheet Forecast
B1: 3 Statement Financial Model
A3: X | B3: Income Statement
B4: Figures in naira | D4: January | E4: February | F4: March | G4: April | H4: May | I4: June | J4: July | K4: August | L4: September | M4: October | N4: November | O4: December
B5: Revenue | D5: =D60*D61 -> 21600000 | E5: =E60*E61 -> 21600000 | F5: =F60*F61 -> 21600000 | G5: =G60*G61 -> 21600000 | H5: =H60*H61 -> 21600000 | I5: =I60*I61 -> 21600000 | J5: =J60*J61 -> 21600000 | K5: =K60*K61 -> 21600000 | ... O5: =O60*O61 -> 21600000
B6: COGS | D6: =-D66*D5 -> -10800000 | E6: =-E66*E5 -> -10800000 | F6: =-F66*F5 -> -10800000 | G6: =-G66*G5 -> -10800000 | H6: =-H66*H5 -> -10800000 | I6: =-I66*I5 -> -10800000 | J6: =-J66*J5 -> -10800000 | K6: =-K66*K5 -> -10800000 | ... O6: =-O66*O5 -> -10800000
B7: Gross Profit | D7: =SUM(D5,D6) -> 10800000 | E7: =SUM(E5,E6) -> 10800000 | F7: =SUM(F5,F6) -> 10800000 | G7: =SUM(G5,G6) -> 10800000 | H7: =SUM(H5,H6) -> 10800000 | I7: =SUM(I5,I6) -> 10800000 | J7: =SUM(J5,J6) -> 10800000 | K7: =SUM(K5,K6) -> 10800000 | ... O7: =SUM(O5,O6) -> 10800000
B8: Ad Spend | D8: =-D5*D67 -> -9720000 | E8: =-E5*E67 -> -9720000 | F8: =-F5*F67 -> -9720000 | G8: =-G5*G67 -> -9720000 | H8: =-H5*H67 -> -9720000 | I8: =-I5*I67 -> -9720000 | J8: =-J5*J67 -> -9720000 | K8: =-K5*K67 -> -9720000 | ... O8: =-O5*O67 -> -9720000
B9: Logistics Costs | D9: =-(D60*D62)+(D60*D63*D64) -> -3900000 | E9: =-(E60*E62)+(E60*E63*E64) -> -3900000 | F9: =-(F60*F62)+(F60*F63*F64) -> -3900000 | G9: =-(G60*G62)+(G60*G63*G64) -> -3900000 | H9: =-(H60*H62)+(H60*H63*H64) -> -3900000 | I9: =-(I60*I62)+(I60*I63*I64) -> -3900000 | J9: =-(J60*J62)+(J60*J63*J64) -> -3900000 | K9: =-(K60*K62)+(K60*K63*K64) -> -3900000 | ... O9: =-(O60*O62)+(O60*O63*O64) -> -3900000
B10: Fixed OpEx | D10: =-D78 -> -850000 | E10: =-E78 -> -850000 | F10: =-F78 -> -850000 | G10: =-G78 -> -850000 | H10: =-H78 -> -850000 | I10: =-I78 -> -850000 | J10: =-J78 -> -850000 | K10: =-K78 -> -850000 | ... O10: =-O78 -> -850000
B11: Operating Profit | D11: =SUM(D7:D10) -> -3670000 | E11: =SUM(E7:E10) -> -3670000 | F11: =SUM(F7:F10) -> -3670000 | G11: =SUM(G7:G10) -> -3670000 | H11: =SUM(H7:H10) -> -3670000 | I11: =SUM(I7:I10) -> -3670000 | J11: =SUM(J7:J10) -> -3670000 | K11: =SUM(K7:K10) -> -3670000 | ... O11: =SUM(O7:O10) -> -3670000
B12: Interest | D12: 0 | E12: 0 | F12: 0 | G12: 0 | H12: 0 | I12: 0 | J12: 0 | K12: 0 | L12: 0 | M12: 0 | N12: 0 | O12: 0
B13: Earnings Before Tax | D13: =SUM(D11:D12) -> -3670000 | E13: =SUM(E11:E12) -> -3670000 | F13: =SUM(F11:F12) -> -3670000 | G13: =SUM(G11:G12) -> -3670000 | H13: =SUM(H11:H12) -> -3670000 | I13: =SUM(I11:I12) -> -3670000 | J13: =SUM(J11:J12) -> -3670000 | K13: =SUM(K11:K12) -> -3670000 | ... O13: =SUM(O11:O12) -> -3670000
B14: Taxes | D14: =IF(D13>0, -D13*D$69, 0) -> 0 | E14: =IF(E13>0, -E13*E$69, 0) -> 0 | F14: =IF(F13>0, -F13*F$69, 0) -> 0 | G14: =IF(G13>0, -G13*G$69, 0) -> 0 | H14: =IF(H13>0, -H13*H$69, 0) -> 0 | I14: =IF(I13>0, -I13*I$69, 0) -> 0 | J14: =IF(J13>0, -J13*J$69, 0) -> 0 | K14: =IF(K13>0, -K13*K$69, 0) -> 0 | ... O14: =IF(O13>0, -O13*O$69, 0) -> 0
B15: Net Income | D15: =SUM(D13,D14) -> -3670000 | E15: =SUM(E13,E14) -> -3670000 | F15: =SUM(F13,F14) -> -3670000 | G15: =SUM(G13,G14) -> -3670000 | H15: =SUM(H13,H14) -> -3670000 | I15: =SUM(I13,I14) -> -3670000 | J15: =SUM(J13,J14) -> -3670000 | K15: =SUM(K13,K14) -> -3670000 | ... O15: =SUM(O13,O14) -> -3670000
A16: X | B16: Balance Sheet
B17: Figures in naira | D17: =D4 -> January | E17: =E4 -> February | F17: =F4 -> March | G17: =G4 -> April | H17: =H4 -> May | I17: =I4 -> June | J17: =J4 -> July | K17: =K4 -> August | ... O17: =O4 -> December
B18: Cash & Cash Equivalents | C18: =8000000 -> 8000000 | D18: =D56 -> 4330000 | E18: =E56 -> 660000 | F18: =F56 -> -3010000 | G18: =G56 -> -6680000 | H18: =H56 -> -10350000 | I18: =I56 -> -14020000 | J18: =J56 -> -17690000 | K18: =K56 -> -21360000 | ... O18: =O56 -> -36040000
B19: Accounts Receivable | C19: 0 | D19: 0 | E19: 0 | F19: 0 | G19: 0 | H19: 0 | I19: 0 | J19: 0 | K19: 0 | L19: 0 | M19: 0 | N19: 0 | O19: 0
B20: Inventory | C20: 18000000 | D20: =D6*-1 -> 10800000 | E20: =E6*-1 -> 10800000 | F20: =F6*-1 -> 10800000 | G20: =G6*-1 -> 10800000 | H20: =H6*-1 -> 10800000 | I20: =I6*-1 -> 10800000 | J20: =J6*-1 -> 10800000 | K20: =K6*-1 -> 10800000 | ... O20: =O6*-1 -> 10800000
B21: Total Current Assets | D21: =SUM(D18:D20) -> 15130000 | E21: =SUM(E18:E20) -> 11460000 | F21: =SUM(F18:F20) -> 7790000 | G21: =SUM(G18:G20) -> 4120000 | H21: =SUM(H18:H20) -> 450000 | I21: =SUM(I18:I20) -> -3220000 | J21: =SUM(J18:J20) -> -6890000 | K21: =SUM(K18:K20) -> -10560000 | ... O21: =SUM(O18:O20) -> -25240000
B22: Total Assets | D22: =D21 -> 15130000 | E22: =E21 -> 11460000 | F22: =F21 -> 7790000 | G22: =G21 -> 4120000 | H22: =H21 -> 450000 | I22: =I21 -> -3220000 | J22: =J21 -> -6890000 | K22: =K21 -> -10560000 | ... O22: =O21 -> -25240000
B24: Accounts Payable | D24: 0 | E24: 0 | F24: 0 | G24: 0 | H24: 0 | I24: 0 | J24: 0 | K24: 0 | L24: 0 | M24: 0 | N24: 0 | O24: 0
B25: Revolver | D25: 0 | E25: 0 | F25: 0 | G25: 0 | H25: 0 | I25: 0 | J25: 0 | K25: 0 | L25: 0 | M25: 0 | N25: 0 | O25: 0
B26: Total Current Liabilities | D26: 0 | E26: 0 | F26: 0 | G26: 0 | H26: 0 | I26: 0 | J26: 0 | K26: 0 | L26: 0 | M26: 0 | N26: 0 | O26: 0
B28: Long Term Debt | D28: 0 | E28: 0 | F28: 0 | G28: 0 | H28: 0 | I28: 0 | J28: 0 | K28: 0 | L28: 0 | M28: 0 | N28: 0 | O28: 0
B29: Total Liabilities | D29: 0 | E29: 0 | F29: 0 | G29: 0 | H29: 0 | I29: 0 | J29: 0 | K29: 0 | L29: 0 | M29: 0 | N29: 0 | O29: 0
B31: Opening Capital | C31: 26000000 | D31: =C18+D20 -> 18800000 | E31: =D31 -> 18800000 | F31: =E31 -> 18800000 | G31: =F31 -> 18800000 | H31: =G31 -> 18800000 | I31: =H31 -> 18800000 | J31: =I31 -> 18800000 | K31: =J31 -> 18800000 | L31: =K31 -> 18800000 | ... O31: =N31 -> 18800000
B32: Retained Earnings | D32: =D15 -> -3670000 | E32: =E15+D32 -> -7340000 | F32: =F15+E32 -> -11010000 | G32: =G15+F32 -> -14680000 | H32: =H15+G32 -> -18350000 | I32: =I15+H32 -> -22020000 | J32: =J15+I32 -> -25690000 | K32: =K15+J32 -> -29360000 | L32: =L15+K32 -> -33030000 | ... O32: =O15+N32 -> -44040000
B33: Total Shareholders' Equity | D33: =SUM(D31,D32) -> 15130000 | E33: =SUM(E31,E32) -> 11460000 | F33: =SUM(F31,F32) -> 7790000 | G33: =SUM(G31,G32) -> 4120000 | H33: =SUM(H31,H32) -> 450000 | I33: =SUM(I31,I32) -> -3220000 | J33: =SUM(J31,J32) -> -6890000 | K33: =SUM(K31,K32) -> -10560000 | ... O33: =SUM(O31,O32) -> -25240000
B35: Total Liabilities & Equity | D35: =SUM(D29,D33) -> 15130000 | E35: =SUM(E29,E33) -> 11460000 | F35: =SUM(F29,F33) -> 7790000 | G35: =SUM(G29,G33) -> 4120000 | H35: =SUM(H29,H33) -> 450000 | I35: =SUM(I29,I33) -> -3220000 | J35: =SUM(J29,J33) -> -6890000 | K35: =SUM(K29,K33) -> -10560000 | ... O35: =SUM(O29,O33) -> -25240000
B36: Balance Sheet Check | D36: =D22-D35 -> 0 | E36: =E22-E35 -> 0 | F36: =F22-F35 -> 0 | G36: =G22-G35 -> 0 | H36: =H22-H35 -> 0 | I36: =I22-I35 -> 0 | J36: =J22-J35 -> 0 | K36: =K22-K35 -> 0 | ... O36: =O22-O35 -> 0
A38: X | B38: Cash Flow Statement
B39: Net Income | D39: =D15 -> -3670000 | E39: =E15 -> -3670000 | F39: =F15 -> -3670000 | G39: =G15 -> -3670000 | H39: =H15 -> -3670000 | I39: =I15 -> -3670000 | J39: =J15 -> -3670000 | K39: =K15 -> -3670000 | ... O39: =O15 -> -3670000
B40: Change in Inventory | D40: 0 | E40: 0 | F40: 0 | G40: 0 | H40: 0 | I40: 0 | J40: 0 | K40: 0 | L40: 0 | M40: 0 | N40: 0 | O40: 0
B41: Change in Accounts Recievable | D41: 0 | E41: 0 | F41: 0 | G41: 0 | H41: 0 | I41: 0 | J41: 0 | K41: 0 | L41: 0 | M41: 0 | N41: 0 | O41: 0
B42: Change in Accounts Payable | D42: 0 | E42: 0 | F42: 0 | G42: 0 | H42: 0 | I42: 0 | J42: 0 | K42: 0 | L42: 0 | M42: 0 | N42: 0 | O42: 0
B43: Cash Flow from Operating Activities | D43: =SUM(D39:D42) -> -3670000 | E43: =SUM(E39:E42) -> -3670000 | F43: =SUM(F39:F42) -> -3670000 | G43: =SUM(G39:G42) -> -3670000 | H43: =SUM(H39:H42) -> -3670000 | I43: =SUM(I39:I42) -> -3670000 | J43: =SUM(J39:J42) -> -3670000 | K43: =SUM(K39:K42) -> -3670000 | ... O43: =SUM(O39:O42) -> -3670000
B45: Capital Expenditures | D45: 0 | E45: 0 | F45: 0 | G45: 0 | H45: 0 | I45: 0 | J45: 0 | K45: 0 | L45: 0 | M45: 0 | N45: 0 | O45: 0
B46: Cash Flow from Investing Activities | D46: =D45 -> 0 | E46: =E45 -> 0 | F46: =F45 -> 0 | G46: =G45 -> 0 | H46: =H45 -> 0 | I46: =I45 -> 0 | J46: =J45 -> 0 | K46: =K45 -> 0 | ... O46: =O45 -> 0
B48: Change in LT Debt | D48: 0 | E48: 0 | F48: 0 | G48: 0 | H48: 0 | I48: 0 | J48: 0 | K48: 0 | L48: 0 | M48: 0 | N48: 0 | O48: 0
...

Sheet Report
B2: DTC Clarity Financial Model
B4: 3-Statement Financial Model | Nigerian E-commerce | 12-Month Projection
B6: Built by: Tobou Egbekun | Analytics Engineer & Financial Modeler
B8: OVERVIEW
B9: This model stress tests the financial survival of a Nigerian DTC brand operating at ₦40M monthly revenue across three distinct scenarios. The analysis quantifies cash runway, profitability thresholds, and insolvency risk under real market conditions including RTO volatility, logistics cost inflation, and Meta ad spend pressure.
C11: KEY ASSUMPTIONS
C13: Assumption | D13: Best Case | E13: Base Case | F13: Worst Case
C14: Monthly Orders | D14: 2500 | E14: 2000 | F14: 1200
C15: Average Order Value | D15: 22000 | E15: 20000 | F15: 18000
C16: Monthly Revenue | D16: 55000000 | E16: 40000000 | F16: 21600000
C17: COGS % | D17: 0.4 | E17: 0.45 | F17: 0.5
C18: Ad Spend % | D18: 0.2 | E18: 0.25 | F18: 0.45
C19: RTO Rate | D19: 0.1 | E19: 0.15 | F19: 0.35
C20: Logistics per Order | D20: 2000 | E20: 2500 | F20: 5000
C22: SCENARIO OUTCOMES
C24: Metric | D24: Best Case | E24: Base Case | F24: Worst Case
C25: Monthly Net Income | D25: 11655000 | E25: 4830000 | F25: Loss
C26: Year End Cash | D26: 150M+ | E26: 65090000 | F26: -36040000
C27: Cash Runway | D27: 13.7 months | E27: 12 months | F27: Insolvent
C28: Survival Status | D28: Healthy | E28: Healthy | F28: Insolvent
B39: KEY FINDINGS
B40: 1. The business is profitable and cash generative under Base and Best Case scenarios, accumulating between ₦66M and ₦150M in cash by December from an ₦8M opening position. 2. A simultaneous RTO spike to 35%, ad spend pressure to 45%, and logistics cost doubling to ₦5,000 per order renders the business insolvent within 60 days — producing a ₦36M cash deficit by December. 3. The primary survival lever is RTO rate. At 35% RTO, logistics costs alone consume ₦147M annually on 2,000 monthly orders — before a single naira is spent on ads or operations.
B42: STRATEGIC RECOMMENDATIONS
B43: 1. BEST CASE: Scale aggressively. Reinvest excess cash into inventory expansion and geographic market development. Consider reducing ad spend % as organic growth compounds. 2. BASE CASE: Protect margins. Monitor RTO rate weekly as the leading indicator of financial health. Build cash reserves toward ₦20M minimum buffer before considering any dividend or expansion spend. 3. WORST CASE: Immediate intervention required. Suspend Meta ad spend, implement order verification protocols to reduce RTO, renegotiate logistics rates or switch providers. The business has less than 60 days before insolvency without intervention.

Sheet Calc
A1: Month | B1: Base Case | C1: Best Case | D1: Worse case
A2: January | B2: 12830000 | C2: 19655000 | D2: 4330000
A3: February | B3: 17660000 | C3: 31310000 | D3: 660000
A4: March | B4: 22490000 | C4: 42965000 | D4: -3010000
A5: April | B5: 27320000 | C5: 54620000 | D5: -6680000
A6: May | B6: 32150000 | C6: 66275000 | D6: -10350000
A7: June | B7: 36980000 | C7: 77930000 | D7: -14020000
A8: July | B8: 41810000 | C8: 89585000 | D8: -17690000
A9: August | B9: 46640000 | C9: 101240000 | D9: -21360000
A10: September | B10: 51470000 | C10: 112895000 | D10: -25030000
A11: October | B11: 56300000 | C11: 124550000 | D11: -28700000
A12: November | B12: 61130000 | C12: 136205000 | D12: -32370000
A13: December | B13: 65960000 | C13: 147860000 | D13: -36040000
